<?xml version="1.0" ?>
<robot name="clean_robot">

  <!-- Init colour -->
  <material name="black">
      <color rgba="0.0 0.0 0.0 1.0"/>
  </material>

  <material name="dark">
    <color rgba="0.3 0.3 0.3 1.0"/>
  </material>
 
  <material name="light_black">
    <color rgba="0.4 0.4 0.4 1.0"/>
  </material>

  <material name="blue">
    <color rgba="0.0 0.0 0.8 1.0"/>
  </material>

  <material name="green">
    <color rgba="0.0 0.8 0.0 1.0"/>
  </material>

  <material name="grey">
    <color rgba="0.5 0.5 0.5 1.0"/>
  </material>

  <material name="orange">
    <color rgba="1.0 0.4235 0.0392 1.0"/>
  </material>

  <material name="brown">
    <color rgba="0.8706 0.8118 0.7647 1.0"/>
  </material>

  <material name="red">
    <color rgba="0.8 0.0 0.0 1.0"/>
  </material>

  <material name="white">
    <color rgba="1.0 1.0 1.0 1.0"/>
  </material>

  <!-- Links -->
  <link name="base_link">
    <visual>
      <origin xyz="0 0 0.045" rpy="0 0 0"/>
      <geometry>
        <cylinder length="0.09" radius="0.175" />
      </geometry>
      <material name="light_black"/>
    </visual>
    <collision>
      <origin xyz="0 0 0" rpy="0 0 0"/>
      <geometry>
        <cylinder length="0.09" radius="0.175" />
      </geometry>
    </collision>
  </link>

  <link name="wheel_left_link">
    <visual>
      <origin xyz="0 0 0" rpy="0 0 0"/>
      <geometry>
        <cylinder length="0.04" radius="0.045" />
      </geometry>
      <material name="dark"/>
    </visual>
    <collision>
      <origin xyz="0 0 0" rpy="0 0 0"/>
      <geometry>
        <cylinder length="0.04" radius="0.045" />
      </geometry>
    </collision>
  </link>

  <link name="wheel_right_link">
    <visual>
      <origin xyz="0 0 0" rpy="0 0 0"/>
      <geometry>
        <cylinder length="0.04" radius="0.045" />
      </geometry>
      <material name="dark"/>
    </visual>
    <collision>
      <origin xyz="0 0 0" rpy="0 0 0"/>
      <geometry>
        <cylinder length="0.04" radius="0.045" />
      </geometry>
    </collision>
  </link>
  
  <link name="imu_link"/>
  <link name="base_scan"/>

  <link name="base_scan_front">
    <visual>
      <origin xyz="0 0 0" rpy="0 0 0"/>
      <geometry>
        <cylinder length="0.0344" radius="0.0176" />
      </geometry>
      <material name="dark"/>
    </visual>
    <collision>
      <origin xyz="0 0 0" rpy="0 0 0"/>
      <geometry>
        <cylinder length="0.0344" radius="0.0176" />
      </geometry>
    </collision>
  </link>

  <link name="base_scan_back">
    <visual>
      <origin xyz="0 0 0" rpy="0 0 0"/>
      <geometry>
        <cylinder length="0.0344" radius="0.0176" />
      </geometry>
      <material name="white"/>
    </visual>
    <collision>
      <origin xyz="0 0 0" rpy="0 0 0"/>
      <geometry>
        <cylinder length="0.0344" radius="0.0176" />
      </geometry>
    </collision>
  </link>

  <!-- Joints -->
  <joint name="wheel_left_joint" type="continuous">
    <parent link="base_link"/>
    <child link="wheel_left_link"/>
    <origin xyz="0 0.135 0" rpy="-1.57 0 0"/>
    <axis xyz="0 0 1"/>
  </joint>

  <joint name="wheel_right_joint" type="continuous">
    <parent link="base_link"/>
    <child link="wheel_right_link"/>
    <origin xyz="0 -0.135 0" rpy="-1.57 0 0"/>
    <axis xyz="0 0 1"/>
  </joint>

  <joint name="imu_joint" type="fixed">
    <parent link="base_link"/>
    <child link="imu_link"/>
    <origin xyz="0 0 0.09" rpy="0 0 0"/>
  </joint>

  <joint name="base_scan_joint" type="fixed">
    <parent link="base_link"/>
    <child link="base_scan"/>
    <origin xyz="0 0 0.155" rpy="0 0 0"/>
  </joint>

  <joint name="scan_front_joint" type="fixed">
    <parent link="base_scan"/>
    <child link="base_scan_front"/>
    <origin xyz="0.115 0 0" rpy="0 0 3.14"/>
  </joint>

  <joint name="scan_back_joint" type="fixed">
    <parent link="base_scan"/>
    <child link="base_scan_back"/>
    <origin xyz="-0.115 0 0" rpy="0 0 0"/>
  </joint>

</robot>
